[2024-10-21T23:06:11.531+0000] {local_task_job_runner.py:123} INFO - ::group::Pre task execution logs
[2024-10-21T23:06:11.649+0000] {taskinstance.py:2612} INFO - Dependencies all met for dep_context=non-requeueable deps ti=<TaskInstance: load_all_data_dag.load_data_to_postgres manual__2024-10-21T23:05:58.369549+00:00 [queued]>
[2024-10-21T23:06:11.720+0000] {taskinstance.py:2612} INFO - Dependencies all met for dep_context=requeueable deps ti=<TaskInstance: load_all_data_dag.load_data_to_postgres manual__2024-10-21T23:05:58.369549+00:00 [queued]>
[2024-10-21T23:06:11.729+0000] {taskinstance.py:2865} INFO - Starting attempt 1 of 1
[2024-10-21T23:06:11.778+0000] {taskinstance.py:2888} INFO - Executing <Task(PythonOperator): load_data_to_postgres> on 2024-10-21 23:05:58.369549+00:00
[2024-10-21T23:06:12.186+0000] {standard_task_runner.py:104} INFO - Running: ['***', 'tasks', 'run', 'load_all_data_dag', 'load_data_to_postgres', 'manual__2024-10-21T23:05:58.369549+00:00', '--job-id', '13', '--raw', '--subdir', 'DAGS_FOLDER/dag.py', '--cfg-path', '/tmp/tmptk3e1mgl']
[2024-10-21T23:06:11.888+0000] {warnings.py:112} WARNING - /home/***/.local/lib/python3.12/site-packages/***/task/task_runner/standard_task_runner.py:70: DeprecationWarning: This process (pid=69) is multi-threaded, use of fork() may lead to deadlocks in the child.
  pid = os.fork()

[2024-10-21T23:06:12.327+0000] {standard_task_runner.py:105} INFO - Job 13: Subtask load_data_to_postgres
[2024-10-21T23:06:12.332+0000] {standard_task_runner.py:72} INFO - Started process 71 to run task
[2024-10-21T23:06:13.851+0000] {task_command.py:467} INFO - Running <TaskInstance: load_all_data_dag.load_data_to_postgres manual__2024-10-21T23:05:58.369549+00:00 [running]> on host 74aef1acb9f1
[2024-10-21T23:06:14.378+0000] {taskinstance.py:3131} INFO - Exporting env vars: AIRFLOW_CTX_DAG_OWNER='***' AIRFLOW_CTX_DAG_ID='load_all_data_dag' AIRFLOW_CTX_TASK_ID='load_data_to_postgres' AIRFLOW_CTX_EXECUTION_DATE='2024-10-21T23:05:58.369549+00:00' AIRFLOW_CTX_TRY_NUMBER='1' AIRFLOW_CTX_DAG_RUN_ID='manual__2024-10-21T23:05:58.369549+00:00'
[2024-10-21T23:06:14.422+0000] {logging_mixin.py:190} INFO - Task instance is in running state
[2024-10-21T23:06:14.423+0000] {logging_mixin.py:190} INFO -  Previous state of the Task instance: queued
[2024-10-21T23:06:14.425+0000] {logging_mixin.py:190} INFO - Current task name:load_data_to_postgres state:running start_date:2024-10-21 23:06:11.656886+00:00
[2024-10-21T23:06:14.426+0000] {logging_mixin.py:190} INFO - Dag name:load_all_data_dag and current dag run status:running
[2024-10-21T23:06:14.428+0000] {taskinstance.py:731} INFO - ::endgroup::
[2024-10-21T23:06:14.455+0000] {logging_mixin.py:190} INFO - Ocurri√≥ un error: [Errno 2] No such file or directory: 'C:/Users/gpost/OneDrive/Documents/prueba_challenge/sales.csv'
[2024-10-21T23:06:14.456+0000] {taskinstance.py:3310} ERROR - Task failed with exception
Traceback (most recent call last):
  File "/home/airflow/.local/lib/python3.12/site-packages/airflow/models/taskinstance.py", line 767, in _execute_task
    result = _execute_callable(context=context, **execute_callable_kwargs)
             ^^^^^^^^^^^^^^^^^^^^^^^^^^^^^^^^^^^^^^^^^^^^^^^^^^^^^^^^^^^^^
  File "/home/airflow/.local/lib/python3.12/site-packages/airflow/models/taskinstance.py", line 733, in _execute_callable
    return ExecutionCallableRunner(
           ^^^^^^^^^^^^^^^^^^^^^^^^
  File "/home/airflow/.local/lib/python3.12/site-packages/airflow/utils/operator_helpers.py", line 252, in run
    return self.func(*args, **kwargs)
           ^^^^^^^^^^^^^^^^^^^^^^^^^^
  File "/home/airflow/.local/lib/python3.12/site-packages/airflow/models/baseoperator.py", line 406, in wrapper
    return func(self, *args, **kwargs)
           ^^^^^^^^^^^^^^^^^^^^^^^^^^^
  File "/home/airflow/.local/lib/python3.12/site-packages/airflow/operators/python.py", line 238, in execute
    return_value = self.execute_callable()
                   ^^^^^^^^^^^^^^^^^^^^^^^
  File "/home/airflow/.local/lib/python3.12/site-packages/airflow/operators/python.py", line 256, in execute_callable
    return runner.run(*self.op_args, **self.op_kwargs)
           ^^^^^^^^^^^^^^^^^^^^^^^^^^^^^^^^^^^^^^^^^^^
  File "/home/airflow/.local/lib/python3.12/site-packages/airflow/utils/operator_helpers.py", line 252, in run
    return self.func(*args, **kwargs)
           ^^^^^^^^^^^^^^^^^^^^^^^^^^
  File "/opt/airflow/dags/dag.py", line 59, in load_data_to_postgres
    cursor.close()
    ^^^^^^
UnboundLocalError: cannot access local variable 'cursor' where it is not associated with a value
[2024-10-21T23:06:14.568+0000] {logging_mixin.py:190} INFO - Task instance in failure state
[2024-10-21T23:06:14.569+0000] {logging_mixin.py:190} INFO - Task start:2024-10-21 23:06:11.656886+00:00 end:2024-10-21 23:06:14.562907+00:00 duration:2.906021
[2024-10-21T23:06:14.570+0000] {logging_mixin.py:190} INFO - Task:<Task(PythonOperator): load_data_to_postgres> dag:<DAG: load_all_data_dag> dagrun:<DagRun load_all_data_dag @ 2024-10-21 23:05:58.369549+00:00: manual__2024-10-21T23:05:58.369549+00:00, state:running, queued_at: 2024-10-21 23:05:58.416562+00:00. externally triggered: True>
[2024-10-21T23:06:14.571+0000] {logging_mixin.py:190} INFO - Failure caused by cannot access local variable 'cursor' where it is not associated with a value
[2024-10-21T23:06:14.572+0000] {taskinstance.py:1225} INFO - Marking task as FAILED. dag_id=load_all_data_dag, task_id=load_data_to_postgres, run_id=manual__2024-10-21T23:05:58.369549+00:00, execution_date=20241021T230558, start_date=20241021T230611, end_date=20241021T230614
[2024-10-21T23:06:14.622+0000] {taskinstance.py:340} INFO - ::group::Post task execution logs
[2024-10-21T23:06:14.626+0000] {standard_task_runner.py:124} ERROR - Failed to execute job 13 for task load_data_to_postgres (cannot access local variable 'cursor' where it is not associated with a value; 71)
Traceback (most recent call last):
  File "/home/airflow/.local/lib/python3.12/site-packages/airflow/task/task_runner/standard_task_runner.py", line 117, in _start_by_fork
    ret = args.func(args, dag=self.dag)
          ^^^^^^^^^^^^^^^^^^^^^^^^^^^^^
  File "/home/airflow/.local/lib/python3.12/site-packages/airflow/cli/cli_config.py", line 49, in command
    return func(*args, **kwargs)
           ^^^^^^^^^^^^^^^^^^^^^
  File "/home/airflow/.local/lib/python3.12/site-packages/airflow/utils/cli.py", line 115, in wrapper
    return f(*args, **kwargs)
           ^^^^^^^^^^^^^^^^^^
  File "/home/airflow/.local/lib/python3.12/site-packages/airflow/cli/commands/task_command.py", line 483, in task_run
    task_return_code = _run_task_by_selected_method(args, _dag, ti)
                       ^^^^^^^^^^^^^^^^^^^^^^^^^^^^^^^^^^^^^^^^^^^^
  File "/home/airflow/.local/lib/python3.12/site-packages/airflow/cli/commands/task_command.py", line 256, in _run_task_by_selected_method
    return _run_raw_task(args, ti)
           ^^^^^^^^^^^^^^^^^^^^^^^
  File "/home/airflow/.local/lib/python3.12/site-packages/airflow/cli/commands/task_command.py", line 341, in _run_raw_task
    return ti._run_raw_task(
           ^^^^^^^^^^^^^^^^^
  File "/home/airflow/.local/lib/python3.12/site-packages/airflow/utils/session.py", line 97, in wrapper
    return func(*args, session=session, **kwargs)
           ^^^^^^^^^^^^^^^^^^^^^^^^^^^^^^^^^^^^^^
  File "/home/airflow/.local/lib/python3.12/site-packages/airflow/models/taskinstance.py", line 3004, in _run_raw_task
    return _run_raw_task(
           ^^^^^^^^^^^^^^
  File "/home/airflow/.local/lib/python3.12/site-packages/airflow/models/taskinstance.py", line 273, in _run_raw_task
    TaskInstance._execute_task_with_callbacks(
  File "/home/airflow/.local/lib/python3.12/site-packages/airflow/models/taskinstance.py", line 3158, in _execute_task_with_callbacks
    result = self._execute_task(context, task_orig)
             ^^^^^^^^^^^^^^^^^^^^^^^^^^^^^^^^^^^^^^
  File "/home/airflow/.local/lib/python3.12/site-packages/airflow/models/taskinstance.py", line 3182, in _execute_task
    return _execute_task(self, context, task_orig)
           ^^^^^^^^^^^^^^^^^^^^^^^^^^^^^^^^^^^^^^^
  File "/home/airflow/.local/lib/python3.12/site-packages/airflow/models/taskinstance.py", line 767, in _execute_task
    result = _execute_callable(context=context, **execute_callable_kwargs)
             ^^^^^^^^^^^^^^^^^^^^^^^^^^^^^^^^^^^^^^^^^^^^^^^^^^^^^^^^^^^^^
  File "/home/airflow/.local/lib/python3.12/site-packages/airflow/models/taskinstance.py", line 733, in _execute_callable
    return ExecutionCallableRunner(
           ^^^^^^^^^^^^^^^^^^^^^^^^
  File "/home/airflow/.local/lib/python3.12/site-packages/airflow/utils/operator_helpers.py", line 252, in run
    return self.func(*args, **kwargs)
           ^^^^^^^^^^^^^^^^^^^^^^^^^^
  File "/home/airflow/.local/lib/python3.12/site-packages/airflow/models/baseoperator.py", line 406, in wrapper
    return func(self, *args, **kwargs)
           ^^^^^^^^^^^^^^^^^^^^^^^^^^^
  File "/home/airflow/.local/lib/python3.12/site-packages/airflow/operators/python.py", line 238, in execute
    return_value = self.execute_callable()
                   ^^^^^^^^^^^^^^^^^^^^^^^
  File "/home/airflow/.local/lib/python3.12/site-packages/airflow/operators/python.py", line 256, in execute_callable
    return runner.run(*self.op_args, **self.op_kwargs)
           ^^^^^^^^^^^^^^^^^^^^^^^^^^^^^^^^^^^^^^^^^^^
  File "/home/airflow/.local/lib/python3.12/site-packages/airflow/utils/operator_helpers.py", line 252, in run
    return self.func(*args, **kwargs)
           ^^^^^^^^^^^^^^^^^^^^^^^^^^
  File "/opt/airflow/dags/dag.py", line 59, in load_data_to_postgres
    cursor.close()
    ^^^^^^
UnboundLocalError: cannot access local variable 'cursor' where it is not associated with a value
[2024-10-21T23:06:14.686+0000] {local_task_job_runner.py:266} INFO - Task exited with return code 1
[2024-10-21T23:06:14.730+0000] {taskinstance.py:3900} INFO - 0 downstream tasks scheduled from follow-on schedule check
[2024-10-21T23:06:14.734+0000] {local_task_job_runner.py:245} INFO - ::endgroup::
